Workbook

Sheet GERAL ENVIOS
S1: 45689 | T1: 46023
S2: 953 | T2: 970
C3: STATUS | D3: QUANT | F3: CAPA | G3: QUANTIDADE | S3: 964 | T3: 1066
C4: APROVADO | D4: =COUNTIF(K:K,"APROVADO") -> 11 | F4: EM DIAGRAMAÇÃO | G4: =COUNTIF(M:M,"EM DIAGRAMAÇÃO") -> 0 | S4: 1019 | T4: 1179
C5: Aguardando Aprovação | D5: =COUNTIF(K:K,"Aguardando Aprovação") -> 81 | F5: EM PRODUÇÃO | G5: =COUNTIF(M:M,"EM PRODUÇÃO") -> 0 | S5: 1084 | T5: 995
C6: DIAGRAMADO | D6: =COUNTIF(K:K,"DIAGRAMADO") -> 3 | F6: CAPA ENTREGUE | G6: =COUNTIF(M:M,"ESTOJO ENTREGUE") -> 0 | S6: 1172 | T6: 972
C7: Sem álbum | D7: =COUNTIF(K:K,"Sem álbum") -> 77 | F7: DIAGRAMADO | G7: =COUNTIF(M:M,"DIAGRAMADO") -> 347 | S7: 988 | T7: 996
C8: EM DIAGRAMAÇÃO | D8: =COUNTIF(K:K,"EM DIAGRAMAÇÃO") -> 0 | F8: TOTAL | G8: =G7+G6+G5+G4 -> 347 | S8: 994 | T8: 1085
C9: Com Modificações | D9: =COUNTIF(K:K,"Com Modificações") -> 10 | S9: 968 | T9: 954
C10: Finalizado | D10: =COUNTIF(K:K,"Finalizado") -> 254 | S10: 957 | T10: 1099
C11: IMPRESSÃO | D11: =COUNTIF(K:K,"IMPRESSÃO") -> 52 | S11: 961 | T11: 1232
C12: PRONTO PARA ENVIO | D12: =COUNTIF(K:K,"PRONTO PARA ENVIO") -> 0 | S12: 971 | T12: 962
C13: COM A BARBARA | D13: =COUNTIF(K:K,"COM A BARBARA") -> 0 | S13: 1103 | T13: 1105
C14: AGUARDANDO FOTO | D14: =COUNTIF(K:K,"AGUARDANDO FOTO") -> 22 | S14: 1173 | T14: 958
C15: TOTAL | D15: =D11+D10+D9+D8+D7+D6+D5+D4+D12+D14+D13 -> 510 | S15: 1177
A18: DOWNLOAD | B18: DATA | C18: CLIENTE | D18: CONT | E18: SGE | F18: TAMANHO | G18: CURSO | H18: CPF | I18: MAISBOOK | J18: Cliente | K18: STATUS | L18: LOTE | M18: CAPA | N18: POSTERS | O18: PRAZO DE ENVIO | P18: DATA DO ENVIO | Q18: DATA DA APROVAÇÃO | R18: PRAZO DE ENTREGA
A19: TRUE | B19: 46183 | C19: Tiago Afonso Vasconcelos De Souza | D19: 964 | E19: =IFERROR(__xludf.DUMMYFUNCTION("IF(C19="""", """", XLOOKUP(TRIM(C19), 'COTRATOS ALBUNS 25.2'!E:E, 'COTRATOS ALBUNS 25.2'!D:D, XLOOKUP(TRIM(C19), IMPORTRANGE(""16smdYggRVyzhu5y9HP2ayvW__ybkjb1nkVsCvZrByLM"", ""'COTRATOS 26.1'!B:B""), IMPORTRANGE(""16smdYggRVyzhu5y9HP2ayvW__ybkjb1nkVsCvZr"&"ByLM"", ""'COTRATOS 26.1'!A:A""), """")))"),84013.0) -> 84013 | F19: Studio Day Moscou 30x20 | G19: PSICOLOGIA | H19: 63637228 | I19: XAEFDS6J | K19: Aguardando Aprovação | M19: DIAGRAMADO | N19: FALSE | O19: =B19+17 -> 46200 | P19: 46265 | R19: =IF(Q19="", "", Q19+60) | AA19: 46288.478
A20: TRUE | B20: 46291 | C20: Adagilza Beatriz bispo da Silva | D20: 1179 | E20: =IFERROR(__xludf.DUMMYFUNCTION("IF(C20="""", """", XLOOKUP(TRIM(C20), 'COTRATOS ALBUNS 25.2'!E:E, 'COTRATOS ALBUNS 25.2'!D:D, XLOOKUP(TRIM(C20), IMPORTRANGE(""16smdYggRVyzhu5y9HP2ayvW__ybkjb1nkVsCvZrByLM"", ""'COTRATOS 26.1'!B:B""), IMPORTRANGE(""16smdYggRVyzhu5y9HP2ayvW__ybkjb1nkVsCvZr"&"ByLM"", ""'COTRATOS 26.1'!A:A""), """")))"),93441.0) -> 93441 | F20: Prime Book 30X20 | G20: BIOMEDICINA | I20: ECKTEZTU | K20: Com Modificações | M20: DIAGRAMADO | N20: FALSE | O20: =B20+17 -> 46308 | R20: =IF(Q20="", "", Q20+60)
A21: TRUE | B21: 46225.743 | C21: Adileny nathacha Costa de Miranda | D21: 994 | E21: =IFERROR(__xludf.DUMMYFUNCTION("IF(C21="""", """", XLOOKUP(TRIM(C21), 'COTRATOS ALBUNS 25.2'!E:E, 'COTRATOS ALBUNS 25.2'!D:D, XLOOKUP(TRIM(C21), IMPORTRANGE(""16smdYggRVyzhu5y9HP2ayvW__ybkjb1nkVsCvZrByLM"", ""'COTRATOS 26.1'!B:B""), IMPORTRANGE(""16smdYggRVyzhu5y9HP2ayvW__ybkjb1nkVsCvZr"&"ByLM"", ""'COTRATOS 26.1'!A:A""), """")))"),67849.0) -> 67849 | F21: Essencial Book 20x20 | G21: ENFERMAGEM | I21: E7EUQX4V | K21: Finalizado | L21: Lote 9 | M21: DIAGRAMADO | N21: TRUE | O21: =B21+17 -> 46242.743 | P21: 46297 | Q21: 46226 | R21: =IF(Q21="", "", Q21+60) -> 46286
A22: TRUE | B22: 46268.426 | C22: Adine Nascimento Belo | D22: 994 | E22: =IFERROR(__xludf.DUMMYFUNCTION("IF(C22="""", """", XLOOKUP(TRIM(C22), 'COTRATOS ALBUNS 25.2'!E:E, 'COTRATOS ALBUNS 25.2'!D:D, XLOOKUP(TRIM(C22), IMPORTRANGE(""16smdYggRVyzhu5y9HP2ayvW__ybkjb1nkVsCvZrByLM"", ""'COTRATOS 26.1'!B:B""), IMPORTRANGE(""16smdYggRVyzhu5y9HP2ayvW__ybkjb1nkVsCvZr"&"ByLM"", ""'COTRATOS 26.1'!A:A""), """")))"),87894.0) -> 87894 | F22: Studio Day Moscou 30x20 | G22: ENFERMAGEM | I22: BHG3GVEA | K22: Finalizado | L22: Lote 3 | M22: DIAGRAMADO | N22: TRUE | O22: =B22+17 -> 46285.426 | P22: 46297 | Q22: =B22 -> 46268.426 | R22: =IF(Q22="", "", Q22+60) -> 46328.426
A23: TRUE | B23: 46268.426 | C23: Adison Da Silva Sobrinho Machado | D23: 6118 | E23: =IFERROR(__xludf.DUMMYFUNCTION("IF(C23="""", """", XLOOKUP(TRIM(C23), 'COTRATOS ALBUNS 25.2'!E:E, 'COTRATOS ALBUNS 25.2'!D:D, XLOOKUP(TRIM(C23), IMPORTRANGE(""16smdYggRVyzhu5y9HP2ayvW__ybkjb1nkVsCvZrByLM"", ""'COTRATOS 26.1'!B:B""), IMPORTRANGE(""16smdYggRVyzhu5y9HP2ayvW__ybkjb1nkVsCvZr"&"ByLM"", ""'COTRATOS 26.1'!A:A""), """")))"),73597.0) -> 73597 | F23: Studio Day Moscou 30x20 | G23: DIREITO | I23: P4AYNW2C | K23: Finalizado | L23: Lote 2 | M23: DIAGRAMADO | N23: TRUE | O23: =B23+17 -> 46285.426 | P23: 46296 | Q23: =B23 -> 46268.426 | R23: =IF(Q23="", "", Q23+60) -> 46328.426
A24: TRUE | B24: 46254 | C24: Ádria Caroline Silva Gomes | D24: 970 | E24: =IFERROR(__xludf.DUMMYFUNCTION("IF(C24="""", """", XLOOKUP(TRIM(C24), 'COTRATOS ALBUNS 25.2'!E:E, 'COTRATOS ALBUNS 25.2'!D:D, XLOOKUP(TRIM(C24), IMPORTRANGE(""16smdYggRVyzhu5y9HP2ayvW__ybkjb1nkVsCvZrByLM"", ""'COTRATOS 26.1'!B:B""), IMPORTRANGE(""16smdYggRVyzhu5y9HP2ayvW__ybkjb1nkVsCvZr"&"ByLM"", ""'COTRATOS 26.1'!A:A""), """")))"),92164.0) -> 92164 | F24: Diamond Book 24X34 | G24: FISIOTERAPIA | I24: ZTWDXHZW | K24: Aguardando Aprovação | N24: FALSE | O24: =B24+17 -> 46271 | P24: 46297 | R24: =IF(Q24="", "", Q24+60)
A25: TRUE | B25: 46234 | C25: Adria Stefane Palheta Gomes | D25: 1099 | E25: =IFERROR(__xludf.DUMMYFUNCTION("IF(C25="""", """", XLOOKUP(TRIM(C25), 'COTRATOS ALBUNS 25.2'!E:E, 'COTRATOS ALBUNS 25.2'!D:D, XLOOKUP(TRIM(C25), IMPORTRANGE(""16smdYggRVyzhu5y9HP2ayvW__ybkjb1nkVsCvZrByLM"", ""'COTRATOS 26.1'!B:B""), IMPORTRANGE(""16smdYggRVyzhu5y9HP2ayvW__ybkjb1nkVsCvZr"&"ByLM"", ""'COTRATOS 26.1'!A:A""), """")))"),95260.0) -> 95260 | F25: Essencial Book 20x20 | G25: LOGISTICA | I25: UWT65Y36 | K25: Aguardando Aprovação | M25: DIAGRAMADO | N25: FALSE | O25: =B25+17 -> 46251 | P25: 46310 | R25: =IF(Q25="", "", Q25+60)
A26: TRUE | B26: 46288 | C26: Adriane Correa Lobo | D26: 937 | E26: =IFERROR(__xludf.DUMMYFUNCTION("IF(C26="""", """", XLOOKUP(TRIM(C26), 'COTRATOS ALBUNS 25.2'!E:E, 'COTRATOS ALBUNS 25.2'!D:D, XLOOKUP(TRIM(C26), IMPORTRANGE(""16smdYggRVyzhu5y9HP2ayvW__ybkjb1nkVsCvZrByLM"", ""'COTRATOS 26.1'!B:B""), IMPORTRANGE(""16smdYggRVyzhu5y9HP2ayvW__ybkjb1nkVsCvZr"&"ByLM"", ""'COTRATOS 26.1'!A:A""), """")))"),92279.0) -> 92279 | F26: Prime Book 30X20 | G26: PEDAGOGIA | I26: EWQHF8KY | K26: Com Modificações | N26: FALSE | O26: =B26+17 -> 46305 | P26: 46309 | R26: =IF(Q26="", "", Q26+60)
A27: TRUE | B27: 46275.751 | C27: Adriele Fernanda Guedes Dos Santos | D27: 964 | E27: =IFERROR(__xludf.DUMMYFUNCTION("IF(C27="""", """", XLOOKUP(TRIM(C27), 'COTRATOS ALBUNS 25.2'!E:E, 'COTRATOS ALBUNS 25.2'!D:D, XLOOKUP(TRIM(C27), IMPORTRANGE(""16smdYggRVyzhu5y9HP2ayvW__ybkjb1nkVsCvZrByLM"", ""'COTRATOS 26.1'!B:B""), IMPORTRANGE(""16smdYggRVyzhu5y9HP2ayvW__ybkjb1nkVsCvZr"&"ByLM"", ""'COTRATOS 26.1'!A:A""), """")))"),85993.0) -> 85993 | F27: Studio Day Berlim 24x34 | G27: CIÊNCIAS CONTÁBEIS | I27: TVFXAXHA | K27: Finalizado | L27: Lote 8 | N27: TRUE | O27: =B27+17 -> 46292.751 | P27: 46297 | Q27: 46219 | R27: =IF(Q27="", "", Q27+60) -> 46279
A28: TRUE | B28: 46295 | C28: Airon Samuel Martins Corrêa | D28: 970 | E28: =IFERROR(__xludf.DUMMYFUNCTION("IF(C28="""", """", XLOOKUP(TRIM(C28), 'COTRATOS ALBUNS 25.2'!E:E, 'COTRATOS ALBUNS 25.2'!D:D, XLOOKUP(TRIM(C28), IMPORTRANGE(""16smdYggRVyzhu5y9HP2ayvW__ybkjb1nkVsCvZrByLM"", ""'COTRATOS 26.1'!B:B""), IMPORTRANGE(""16smdYggRVyzhu5y9HP2ayvW__ybkjb1nkVsCvZr"&"ByLM"", ""'COTRATOS 26.1'!A:A""), """")))"),94451.0) -> 94451 | F28: Prime Book 30X20 | G28: EDUCAÇAO FISICA | I28: 3EPS3RXU | K28: Aguardando Aprovação | M28: DIAGRAMADO | N28: FALSE | O28: =B28+17 -> 46312 | P28: 46310 | R28: =IF(Q28="", "", Q28+60)
A29: TRUE | B29: 46255 | C29: Alan Justino Nascimento | D29: 904 | E29: =IFERROR(__xludf.DUMMYFUNCTION("IF(C29="""", """", XLOOKUP(TRIM(C29), 'COTRATOS ALBUNS 25.2'!E:E, 'COTRATOS ALBUNS 25.2'!D:D, XLOOKUP(TRIM(C29), IMPORTRANGE(""16smdYggRVyzhu5y9HP2ayvW__ybkjb1nkVsCvZrByLM"", ""'COTRATOS 26.1'!B:B""), IMPORTRANGE(""16smdYggRVyzhu5y9HP2ayvW__ybkjb1nkVsCvZr"&"ByLM"", ""'COTRATOS 26.1'!A:A""), """")))"),84886.0) -> 84886 | F29: Moscou 30X20 | G29: ENFERMAGEM | I29: 8H4YYU7N | K29: DIAGRAMADO | N29: FALSE | O29: =B29+17 -> 46272 | R29: =IF(Q29="", "", Q29+60)
A30: TRUE | B30: 46297 | C30: Alanna Da Silva Do Vale | D30: 860 | E30: =IFERROR(__xludf.DUMMYFUNCTION("IF(C30="""", """", XLOOKUP(TRIM(C30), 'COTRATOS ALBUNS 25.2'!E:E, 'COTRATOS ALBUNS 25.2'!D:D, XLOOKUP(TRIM(C30), IMPORTRANGE(""16smdYggRVyzhu5y9HP2ayvW__ybkjb1nkVsCvZrByLM"", ""'COTRATOS 26.1'!B:B""), IMPORTRANGE(""16smdYggRVyzhu5y9HP2ayvW__ybkjb1nkVsCvZr"&"ByLM"", ""'COTRATOS 26.1'!A:A""), """")))"),88172.0) -> 88172 | F30: Studio Day Berlim 24x34 | G30: FISIOTERAPIA | I30: 4ZF6AY2T | K30: Finalizado | L30: Lote 13 | M30: DIAGRAMADO | N30: FALSE | O30: =B30+17 -> 46314 | P30: 46297 | Q30: 46245 | R30: =IF(Q30="", "", Q30+60) -> 46305
A31: TRUE | B31: 46256 | C31: Alberto Nícollas Jhoyos Sarubbi De Almeida | D31: 970 | E31: =IFERROR(__xludf.DUMMYFUNCTION("IF(C31="""", """", XLOOKUP(TRIM(C31), 'COTRATOS ALBUNS 25.2'!E:E, 'COTRATOS ALBUNS 25.2'!D:D, XLOOKUP(TRIM(C31), IMPORTRANGE(""16smdYggRVyzhu5y9HP2ayvW__ybkjb1nkVsCvZrByLM"", ""'COTRATOS 26.1'!B:B""), IMPORTRANGE(""16smdYggRVyzhu5y9HP2ayvW__ybkjb1nkVsCvZr"&"ByLM"", ""'COTRATOS 26.1'!A:A""), """")))"),94539.0) -> 94539 | F31: Prime Book 30X20 | G31: ENGENHARIA CIVIL | I31: 3ANNCRNA | K31: Sem álbum | N31: FALSE | O31: =B31+17 -> 46273 | R31: =IF(Q31="", "", Q31+60)
A32: TRUE | B32: 46251 | C32: Aldenise Silva de Nazaré | D32: 1084 | E32: =IFERROR(__xludf.DUMMYFUNCTION("IF(C32="""", """", XLOOKUP(TRIM(C32), 'COTRATOS ALBUNS 25.2'!E:E, 'COTRATOS ALBUNS 25.2'!D:D, XLOOKUP(TRIM(C32), IMPORTRANGE(""16smdYggRVyzhu5y9HP2ayvW__ybkjb1nkVsCvZrByLM"", ""'COTRATOS 26.1'!B:B""), IMPORTRANGE(""16smdYggRVyzhu5y9HP2ayvW__ybkjb1nkVsCvZr"&"ByLM"", ""'COTRATOS 26.1'!A:A""), """")))"),85926.0) -> 85926 | F32: Studio Day Berlim 24x34 | G32: PSICOLOGIA | I32: 57HRM4BF | K32: Aguardando Aprovação | M32: DIAGRAMADO | N32: FALSE | O32: =B32+17 -> 46268 | P32: 46300 | R32: =IF(Q32="", "", Q32+60)
A33: TRUE | B33: 46275.752 | C33: Alessandro Batista Lira | D33: 1172 | E33: =IFERROR(__xludf.DUMMYFUNCTION("IF(C33="""", """", XLOOKUP(TRIM(C33), 'COTRATOS ALBUNS 25.2'!E:E, 'COTRATOS ALBUNS 25.2'!D:D, XLOOKUP(TRIM(C33), IMPORTRANGE(""16smdYggRVyzhu5y9HP2ayvW__ybkjb1nkVsCvZrByLM"", ""'COTRATOS 26.1'!B:B""), IMPORTRANGE(""16smdYggRVyzhu5y9HP2ayvW__ybkjb1nkVsCvZr"&"ByLM"", ""'COTRATOS 26.1'!A:A""), """")))"),85487.0) -> 85487 | F33: Studio Day Moscou 30x20 | G33: LOGISTICA | I33: KFZDPAC5 | K33: Finalizado | L33: Lote 8 | N33: TRUE | O33: =B33+17 -> 46292.752 | P33: 46297 | Q33: 46219 | R33: =IF(Q33="", "", Q33+60) -> 46279
A34: TRUE | B34: 46297 | C34: Aléx Paulo Costa de Nazaré | D34: 961 | E34: =IFERROR(__xludf.DUMMYFUNCTION("IF(C34="""", """", XLOOKUP(TRIM(C34), 'COTRATOS ALBUNS 25.2'!E:E, 'COTRATOS ALBUNS 25.2'!D:D, XLOOKUP(TRIM(C34), IMPORTRANGE(""16smdYggRVyzhu5y9HP2ayvW__ybkjb1nkVsCvZrByLM"", ""'COTRATOS 26.1'!B:B""), IMPORTRANGE(""16smdYggRVyzhu5y9HP2ayvW__ybkjb1nkVsCvZr"&"ByLM"", ""'COTRATOS 26.1'!A:A""), """")))"),73467.0) -> 73467 | F34: Diamond Book 24X34 | G34: ADMINISTRAÇÃO | I34: D7F6WZRH | K34: IMPRESSÃO | L34: Lote 15 | M34: DIAGRAMADO | N34: FALSE | O34: =B34+17 -> 46314 | P34: 46297 | Q34: 46287 | R34: =IF(Q34="", "", Q34+60) -> 46347
A35: TRUE | B35: 46268.426 | C35: Alice Da Silva E Souza | D35: 850 | E35: =IFERROR(__xludf.DUMMYFUNCTION("IF(C35="""", """", XLOOKUP(TRIM(C35), 'COTRATOS ALBUNS 25.2'!E:E, 'COTRATOS ALBUNS 25.2'!D:D, XLOOKUP(TRIM(C35), IMPORTRANGE(""16smdYggRVyzhu5y9HP2ayvW__ybkjb1nkVsCvZrByLM"", ""'COTRATOS 26.1'!B:B""), IMPORTRANGE(""16smdYggRVyzhu5y9HP2ayvW__ybkjb1nkVsCvZr"&"ByLM"", ""'COTRATOS 26.1'!A:A""), """")))"),75788.0) -> 75788 | F35: Studio Day Berlim 24x34 | G35: FARMÁCIA | I35: PHDXKU5M | K35: Finalizado | L35: Lote 4 | M35: DIAGRAMADO | N35: TRUE | O35: =B35+17 -> 46285.426 | P35: 46297 | Q35: 46203 | R35: =IF(Q35="", "", Q35+60) -> 46263
A36: TRUE | B36: 46276 | C36: Alice Gabriely Frota de Oliveira | D36: 1172 | E36: =IFERROR(__xludf.DUMMYFUNCTION("IF(C36="""", """", XLOOKUP(TRIM(C36), 'COTRATOS ALBUNS 25.2'!E:E, 'COTRATOS ALBUNS 25.2'!D:D, XLOOKUP(TRIM(C36), IMPORTRANGE(""16smdYggRVyzhu5y9HP2ayvW__ybkjb1nkVsCvZrByLM"", ""'COTRATOS 26.1'!B:B""), IMPORTRANGE(""16smdYggRVyzhu5y9HP2ayvW__ybkjb1nkVsCvZr"&"ByLM"", ""'COTRATOS 26.1'!A:A""), """")))"),86092.0) -> 86092 | F36: Studio Day Moscou 30x20 | G36: DESIGN GRAFICO | I36: UZBU6RHR | K36: AGUARDANDO FOTO | N36: FALSE | O36: =B36+17 -> 46293 | R36: =IF(Q36="", "", Q36+60)
A37: TRUE | B37: 46297 | C37: Aline da Costa Viana | D37: 970 | E37: =IFERROR(__xludf.DUMMYFUNCTION("IF(C37="""", """", XLOOKUP(TRIM(C37), 'COTRATOS ALBUNS 25.2'!E:E, 'COTRATOS ALBUNS 25.2'!D:D, XLOOKUP(TRIM(C37), IMPORTRANGE(""16smdYggRVyzhu5y9HP2ayvW__ybkjb1nkVsCvZrByLM"", ""'COTRATOS 26.1'!B:B""), IMPORTRANGE(""16smdYggRVyzhu5y9HP2ayvW__ybkjb1nkVsCvZr"&"ByLM"", ""'COTRATOS 26.1'!A:A""), """")))"),90164.0) -> 90164 | F37: Prime Book 30X20 | G37: DIREITO | I37: 7DEHCLLA | K37: IMPRESSÃO | L37: Lote 15 | M37: DIAGRAMADO | N37: FALSE | O37: =B37+17 -> 46314 | P37: 46297 | Q37: 46288 | R37: =IF(Q37="", "", Q37+60) -> 46348
A38: TRUE | B38: 46297 | C38: Aline Da Rocha Lemos | D38: 1172 | E38: =IFERROR(__xludf.DUMMYFUNCTION("IF(C38="""", """", XLOOKUP(TRIM(C38), 'COTRATOS ALBUNS 25.2'!E:E, 'COTRATOS ALBUNS 25.2'!D:D, XLOOKUP(TRIM(C38), IMPORTRANGE(""16smdYggRVyzhu5y9HP2ayvW__ybkjb1nkVsCvZrByLM"", ""'COTRATOS 26.1'!B:B""), IMPORTRANGE(""16smdYggRVyzhu5y9HP2ayvW__ybkjb1nkVsCvZr"&"ByLM"", ""'COTRATOS 26.1'!A:A""), """")))"),86996.0) -> 86996 | F38: Studio Day Berlim 24x34 | G38: CIÊNCIAS CONTÁBEIS | I38: 63VRYPE8 | K38: Finalizado | L38: Lote 12 | M38: DIAGRAMADO | N38: FALSE | O38: =B38+17 -> 46314 | P38: 46297 | Q38: 46251 | R38: =IF(Q38="", "", Q38+60) -> 46311
A39: TRUE | B39: 46297 | C39: Aline Katrini Ramos Menezes | D39: 958 | E39: =IFERROR(__xludf.DUMMYFUNCTION("IF(C39="""", """", XLOOKUP(TRIM(C39), 'COTRATOS ALBUNS 25.2'!E:E, 'COTRATOS ALBUNS 25.2'!D:D, XLOOKUP(TRIM(C39), IMPORTRANGE(""16smdYggRVyzhu5y9HP2ayvW__ybkjb1nkVsCvZrByLM"", ""'COTRATOS 26.1'!B:B""), IMPORTRANGE(""16smdYggRVyzhu5y9HP2ayvW__ybkjb1nkVsCvZr"&"ByLM"", ""'COTRATOS 26.1'!A:A""), """")))"),85224.0) -> 85224 | F39: Essencial Book 20x20 | G39: ENFERMAGEM | I39: 59BL4WYM | K39: IMPRESSÃO | L39: Lote 15 | N39: FALSE | O39: =B39+17 -> 46314 | P39: 46297 | Q39: 46287 | R39: =IF(Q39="", "", Q39+60) -> 46347
A40: TRUE | B40: 46283 | C40: Alinne Carvalho Siqueira | D40: 896 | E40: =IFERROR(__xludf.DUMMYFUNCTION("IF(C40="""", """", XLOOKUP(TRIM(C40), 'COTRATOS ALBUNS 25.2'!E:E, 'COTRATOS ALBUNS 25.2'!D:D, XLOOKUP(TRIM(C40), IMPORTRANGE(""16smdYggRVyzhu5y9HP2ayvW__ybkjb1nkVsCvZrByLM"", ""'COTRATOS 26.1'!B:B""), IMPORTRANGE(""16smdYggRVyzhu5y9HP2ayvW__ybkjb1nkVsCvZr"&"ByLM"", ""'COTRATOS 26.1'!A:A""), """")))"),87367.0) -> 87367 | F40: Prime Book 30X20 | G40: DIREITO | I40: 939PX9PU | K40: Aguardando Aprovação | M40: DIAGRAMADO | N40: FALSE | O40: =B40+17 -> 46300 | P40: 46309 | R40: =IF(Q40="", "", Q40+60)
A41: TRUE | B41: 46268.426 | C41: Allan Da Silva Marvão | D41: 1084 | E41: =IFERROR(__xludf.DUMMYFUNCTION("IF(C41="""", """", XLOOKUP(TRIM(C41), 'COTRATOS ALBUNS 25.2'!E:E, 'COTRATOS ALBUNS 25.2'!D:D, XLOOKUP(TRIM(C41), IMPORTRANGE(""16smdYggRVyzhu5y9HP2ayvW__ybkjb1nkVsCvZrByLM"", ""'COTRATOS 26.1'!B:B""), IMPORTRANGE(""16smdYggRVyzhu5y9HP2ayvW__ybkjb1nkVsCvZr"&"ByLM"", ""'COTRATOS 26.1'!A:A""), """")))"),77467.0) -> 77467 | F41: Studio Day Berlim 24x34 | G41: FARMÁCIA | I41: WJGND7JX | K41: Finalizado | L41: Lote 1 | M41: DIAGRAMADO | N41: TRUE | O41: =B41+17 -> 46285.426 | P41: 46297 | Q41: =B41 -> 46268.426 | R41: =IF(Q41="", "", Q41+60) -> 46328.426
A42: TRUE | B42: 46268.426 | C42: Allan Delon Corrêa Ramos | D42: 971 | E42: =IFERROR(__xludf.DUMMYFUNCTION("IF(C42="""", """", XLOOKUP(TRIM(C42), 'COTRATOS ALBUNS 25.2'!E:E, 'COTRATOS ALBUNS 25.2'!D:D, XLOOKUP(TRIM(C42), IMPORTRANGE(""16smdYggRVyzhu5y9HP2ayvW__ybkjb1nkVsCvZrByLM"", ""'COTRATOS 26.1'!B:B""), IMPORTRANGE(""16smdYggRVyzhu5y9HP2ayvW__ybkjb1nkVsCvZr"&"ByLM"", ""'COTRATOS 26.1'!A:A""), """")))"),86806.0) -> 86806 | F42: Studio Day Moscou 30x20 | G42: ADS- ANALISE E DESENVOLVIMENTO DE SISTEMA | I42: RMUPKBU3 | K42: Finalizado | L42: Lote 2 | M42: DIAGRAMADO | N42: TRUE | O42: =B42+17 -> 46285.426 | P42: 46176 | Q42: =B42 -> 46268.426 | R42: =IF(Q42="", "", Q42+60) -> 46328.426
...

Sheet Página46
A1: Tiago Afonso Vasconcelos De Souza | B1: 964 | C1: 84013 | D1: Studio Day Moscou 30x20 | E1: PSICOLOGIA | F1: 63637228 | G1: XAEFDS6J | I1: Aguardando Aprovação
A2: Ádria Caroline Silva Gomes | B2: 970 | C2: 92164 | D2: Diamond Book 24X34 | E2: FISIOTERAPIA | G2: ZTWDXHZW | I2: Aguardando Aprovação
A3: Adria Stefane Palheta Gomes | B3: 1099 | C3: 95260 | D3: Essencial Book 20x20 | E3: LOGISTICA | G3: UWT65Y36 | I3: Aguardando Aprovação
A4: Airon Samuel Martins Corrêa | B4: 970 | C4: 94451 | D4: Prime Book 30X20 | E4: EDUCAÇAO FISICA | G4: 3EPS3RXU | I4: Aguardando Aprovação
A5: Aldenise Silva de Nazaré | B5: 1084 | C5: 85926 | D5: Studio Day Berlim 24x34 | E5: PSICOLOGIA | G5: 57HRM4BF | I5: Aguardando Aprovação
A6: Alinne Carvalho Siqueira | B6: 896 | C6: 87367 | D6: Prime Book 30X20 | E6: DIREITO | G6: 939PX9PU | I6: Aguardando Aprovação
A7: Amanda Janaina Silva Lobato | B7: 972 | C7: 95114 | D7: Prime Book 30X20 | E7: NUTRIÇÃO | G7: YD6NK3R6 | I7: Aguardando Aprovação
A8: Amanda Larissa Caldas Duarte | B8: 1172 | C8: 85250 | D8: Studio Day Moscou 30x20 | E8: ODONTOLOGIA | G8: GYCP3TAQ | I8: Aguardando Aprovação
A9: Ana Caroline De Sousa Cohen | B9: 968 | C9: 86778 | D9: Studio Day Moscou 30x20 | E9: RADIOLOGIA | G9: 3693AA65 | I9: Aguardando Aprovação
A10: Ana Cláudia Dos Santos Couto | B10: 996 | C10: 86123 | D10: Diamond Book 24X34 | E10: ENFERMAGEM | G10: 73S9MB6F | I10: Aguardando Aprovação
A11: Ana Claudia Reis Rocha | B11: 1066 | C11: 70391 | D11: Prime Book 30X20 | E11: ENFERMAGEM | G11: HZCHW7RC | I11: Aguardando Aprovação
A12: Ana Luiza Pinheiro Barreto | B12: 1172 | C12: 86106 | D12: Studio Day Berlim 24x34 | E12: PEDAGOGIA | G12: TN58YTWA | I12: Aguardando Aprovação
A13: Andreza Kerolayne Rodrigues De Moraes | B13: 1179 | C13: 94498 | D13: Diamond Book 24X34 | E13: CIÊNCIAS CONTÁBEIS | G13: U2YVF4XA | I13: Aguardando Aprovação
... A76: Thamyris Dos Santos Cunha | B76: 895 | C76: 86373 | D76: Studio Day Moscou 30x20 | E76: BIOMEDICINA | G76: N3EFQJLL | I76: Aguardando Aprovação
A77: Thayane Carolina Costa Paiva | B77: 1172 | C77: 85614 | D77: Studio Day Moscou 30x20 | E77: DESIGN GRAFICO | G77: GQV9VC85 | H77: UNINORTE | I77: Aguardando Aprovação
A78: Vyctor Kelvyn De Almeida Carvalho | B78: 971 | C78: 84957 | D78: Studio Day Berlim 24x34 | E78: ADS- ANALISE E DESENVOLVIMENTO DE SISTEMA | G78: N64WPF9C | I78: Aguardando Aprovação
A79: Wanessa Lira Nascimento | B79: 1172 | C79: 86534 | D79: Studio Day Moscou 30x20 | E79: FARMÁCIA | G79: 3ZY4P2T5 | I79: Aguardando Aprovação
A80: Wesneyanny Eduarda Ramos Pires | B80: 1177 | C80: 88244 | D80: Moscou 30X20 | E80: PSICOLOGIA | G80: NFRAPJJH | I80: Aguardando Aprovação
A81: YARA KAROLYNE RUFINO DE AZEVEDO | B81: 1066 | C81: 85181 | D81: Essencial Book 20x20 | E81: DIREITO | G81: QCX8QXPX | I81: Aguardando Aprovação

Sheet COTRATOS ALBUNS 25.2
A1: FACULDADES — RESUMO DE VENDAS E PRODUÇÃO 25.2
A3: Contrato | B3: INSTITUIÇÃO | C3: Total Vendido | D3: Pendente de Escolha | E3: Entregue | F3: Em IMPRESÃO | G3: IMPRESSO | H3: Em Aprovação | I3: DIAGRAMADOS | J3: Cancelados
A4: 953 | B4: UNIP BELEM | C4: =COUNTIF(H32:H1957, A4 & "*") -> 41 | D4: =COUNTIFS(H:H, A4 & "*", I:I, "NAO ESTA NA PLANILHA") -> 23 | E4: =COUNTIFS(H:H, A4 & "*", C:C, "Entregue") -> 0 | F4: =COUNTIFS(H:H, A4 & "*", I:I,"IMPRESSÃO") -> 1 | G4: =COUNTIFS(H:H, A4 & "*", C:C, "Entregue") + COUNTIFS(H:H, A4 & "*", C:C, "No Estoque") + COUNTIFS(H:H, A4 & "*", I:I, "PRONTO") -> 0 | H4: =COUNTIFS(H32:H1957, A4 & "*", I32:I1957,"AGUARDANDO APROVAÇÃO") -> 4 | I4: =COUNTIFS(H32:H1981, A4 & CHAR(42), I32:I1981, "IMPRESSÃO") + COUNTIFS(H32:H1981, A4 & CHAR(42), I32:I1981, "AGUARDANDO APROVAÇÃO") + COUNTIFS(H32:H1981, A4 & CHAR(42), I32:I1981, "APROVADO")+ COUNTIFS(H32:H1981, A4 & CHAR(42), I32:I1981, "DIAGRAMADO") -> 5 | J4: =COUNTIFS(H32:H1978,A4 & "*", C32:C1978, "Cancelado") -> 0
A5: 964 | B5: UNAMA GENTIL | C5: =COUNTIF(H33:H1958, A5 & "*") -> 32 | D5: =COUNTIFS(H:H, A5 & "*", I:I, "NAO ESTA NA PLANILHA") -> 18 | E5: =COUNTIFS(H:H, A5 & "*", C:C, "Entregue") -> 1 | F5: =COUNTIFS(H:H, A5 & "*", I:I,"IMPRESSÃO") -> 1 | G5: =COUNTIFS(H:H, A5 & "*", C:C, "Entregue") + COUNTIFS(H:H, A5 & "*", C:C, "No Estoque") + COUNTIFS(H:H, A5 & "*", I:I, "PRONTO") -> 1 | H5: =COUNTIFS(H33:H1958, A5 & "*", I33:I1958,"AGUARDANDO APROVAÇÃO") -> 2 | I5: =COUNTIFS(H33:H1982, A5 & CHAR(42), I33:I1982, "IMPRESSÃO") + COUNTIFS(H33:H1982, A5 & CHAR(42), I33:I1982, "AGUARDANDO APROVAÇÃO") + COUNTIFS(H33:H1982, A5 & CHAR(42), I33:I1982, "APROVADO")+ COUNTIFS(H33:H1982, A5 & CHAR(42), I33:I1982, "DIAGRAMADO") -> 3 | J5: =COUNTIFS(H33:H1979,A5 & "*", C33:C1979, "Cancelado") -> 0
A6: 1019 | B6: ESTACIO | C6: =COUNTIF(H34:H1959, A6 & "*") -> 16 | D6: =COUNTIFS(H:H, A6 & "*", I:I, "NAO ESTA NA PLANILHA") -> 6 | E6: =COUNTIFS(H:H, A6 & "*", C:C, "Entregue") -> 0 | F6: =COUNTIFS(H:H, A6 & "*", I:I,"IMPRESSÃO") -> 0 | G6: =COUNTIFS(H:H, A6 & "*", C:C, "Entregue") + COUNTIFS(H:H, A6 & "*", C:C, "No Estoque") + COUNTIFS(H:H, A6 & "*", I:I, "PRONTO") -> 0 | H6: =COUNTIFS(H34:H1959, A6 & "*", I34:I1959,"AGUARDANDO APROVAÇÃO") -> 2 | I6: =COUNTIFS(H34:H1983, A6 & CHAR(42), I34:I1983, "IMPRESSÃO") + COUNTIFS(H34:H1983, A6 & CHAR(42), I34:I1983, "AGUARDANDO APROVAÇÃO") + COUNTIFS(H34:H1983, A6 & CHAR(42), I34:I1983, "APROVADO")+ COUNTIFS(H34:H1983, A6 & CHAR(42), I34:I1983, "DIAGRAMADO") -> 2 | J6: =COUNTIFS(H34:H1980,A6 & "*", C34:C1980, "Cancelado") -> 0 | Q6: R
A7: 1084 | B7: UNMA PARQUE SHOPPING | C7: =COUNTIF(H35:H1960, A7 & "*") -> 36 | D7: =COUNTIFS(H:H, A7 & "*", I:I, "NAO ESTA NA PLANILHA") -> 13 | E7: =COUNTIFS(H:H, A7 & "*", C:C, "Entregue") -> 2 | F7: =COUNTIFS(H:H, A7 & "*", I:I,"IMPRESSÃO") -> 0 | G7: =COUNTIFS(H:H, A7 & "*", C:C, "Entregue") + COUNTIFS(H:H, A7 & "*", C:C, "No Estoque") + COUNTIFS(H:H, A7 & "*", I:I, "PRONTO") -> 4 | H7: =COUNTIFS(H35:H1960, A7 & "*", I35:I1960,"AGUARDANDO APROVAÇÃO") -> 5 | I7: =COUNTIFS(H35:H1984, A7 & CHAR(42), I35:I1984, "IMPRESSÃO") + COUNTIFS(H35:H1984, A7 & CHAR(42), I35:I1984, "AGUARDANDO APROVAÇÃO") + COUNTIFS(H35:H1984, A7 & CHAR(42), I35:I1984, "APROVADO")+ COUNTIFS(H35:H1984, A7 & CHAR(42), I35:I1984, "DIAGRAMADO") -> 5 | J7: =COUNTIFS(H35:H1981,A7 & "*", C35:C1981, "Cancelado") -> 1
A8: 1172 | B8: MANAUS | C8: =COUNTIF(H36:H1961, A8 & "*") -> 166 | D8: =COUNTIFS(H:H, A8 & "*", I:I, "NAO ESTA NA PLANILHA") -> 62 | E8: =COUNTIFS(H:H, A8 & "*", C:C, "Entregue") -> 0 | F8: =COUNTIFS(H:H, A8 & "*", I:I,"IMPRESSÃO") -> 15 | G8: =COUNTIFS(H:H, A8 & "*", C:C, "Entregue") + COUNTIFS(H:H, A8 & "*", C:C, "No Estoque") + COUNTIFS(H:H, A8 & "*", I:I, "PRONTO") -> 0 | H8: =COUNTIFS(H36:H1961, A8 & "*", I36:I1961,"AGUARDANDO APROVAÇÃO") -> 16 | I8: =COUNTIFS(H36:H1985, A8 & CHAR(42), I36:I1985, "IMPRESSÃO") + COUNTIFS(H36:H1985, A8 & CHAR(42), I36:I1985, "AGUARDANDO APROVAÇÃO") + COUNTIFS(H36:H1985, A8 & CHAR(42), I36:I1985, "APROVADO")+ COUNTIFS(H36:H1985, A8 & CHAR(42), I36:I1985, "DIAGRAMADO") -> 36 | J8: =COUNTIFS(H36:H1982,A8 & "*", C36:C1982, "Cancelado") -> 0
A9: 988 | B9: COSMOPOLITA | C9: =COUNTIF(H37:H1962, A9 & "*") -> 21 | D9: =COUNTIFS(H:H, A9 & "*", I:I, "NAO ESTA NA PLANILHA") -> 8 | E9: =COUNTIFS(H:H, A9 & "*", C:C, "Entregue") -> 1 | F9: =COUNTIFS(H:H, A9 & "*", I:I,"IMPRESSÃO") -> 1 | G9: =COUNTIFS(H:H, A9 & "*", C:C, "Entregue") + COUNTIFS(H:H, A9 & "*", C:C, "No Estoque") + COUNTIFS(H:H, A9 & "*", I:I, "PRONTO") -> 1 | H9: =COUNTIFS(H37:H1962, A9 & "*", I37:I1962,"AGUARDANDO APROVAÇÃO") -> 1 | I9: =COUNTIFS(H37:H1986, A9 & CHAR(42), I37:I1986, "IMPRESSÃO") + COUNTIFS(H37:H1986, A9 & CHAR(42), I37:I1986, "AGUARDANDO APROVAÇÃO") + COUNTIFS(H37:H1986, A9 & CHAR(42), I37:I1986, "APROVADO")+ COUNTIFS(H37:H1986, A9 & CHAR(42), I37:I1986, "DIAGRAMADO") -> 2 | J9: =COUNTIFS(H37:H1983,A9 & "*", C37:C1983, "Cancelado") -> 0
A10: 994 | B10: UNAMA ANANIDEUA | C10: =COUNTIF(H38:H1963, A10 & "*") -> 60 | D10: =COUNTIFS(H:H, A10 & "*", I:I, "NAO ESTA NA PLANILHA") -> 21 | E10: =COUNTIFS(H:H, A10 & "*", C:C, "Entregue") -> 3 | F10: =COUNTIFS(H:H, A10 & "*", I:I,"IMPRESSÃO") -> 2 | G10: =COUNTIFS(H:H, A10 & "*", C:C, "Entregue") + COUNTIFS(H:H, A10 & "*", C:C, "No Estoque") + COUNTIFS(H:H, A10 & "*", I:I, "PRONTO") -> 3 | H10: =COUNTIFS(H38:H1963, A10 & "*", I38:I1963,"AGUARDANDO APROVAÇÃO") -> 4 | I10: =COUNTIFS(H38:H1987, A10 & CHAR(42), I38:I1987, "IMPRESSÃO") + COUNTIFS(H38:H1987, A10 & CHAR(42), I38:I1987, "AGUARDANDO APROVAÇÃO") + COUNTIFS(H38:H1987, A10 & CHAR(42), I38:I1987, "APROVADO")+ COUNTIFS(H38:H1987, A10 & CHAR(42), I38:I1987, "DIAGRAMADO") -> 7 | J10: =COUNTIFS(H38:H1984,A10 & "*", C38:C1984, "Cancelado") -> 0
A11: 968 | B11: UNAMA SANTAREM | C11: =COUNTIF(H39:H1964, A11 & "*") -> 72 | D11: =COUNTIFS(H:H, A11 & "*", I:I, "NAO ESTA NA PLANILHA") -> 20 | E11: =COUNTIFS(H:H, A11 & "*", C:C, "Entregue") -> 3 | F11: =COUNTIFS(H:H, A11 & "*", I:I,"IMPRESSÃO") -> 1 | G11: =COUNTIFS(H:H, A11 & "*", C:C, "Entregue") + COUNTIFS(H:H, A11 & "*", C:C, "No Estoque") + COUNTIFS(H:H, A11 & "*", I:I, "PRONTO") -> 3 | H11: =COUNTIFS(H39:H1964, A11 & "*", I39:I1964,"AGUARDANDO APROVAÇÃO") -> 9 | I11: =COUNTIFS(H39:H1988, A11 & CHAR(42), I39:I1988, "IMPRESSÃO") + COUNTIFS(H39:H1988, A11 & CHAR(42), I39:I1988, "AGUARDANDO APROVAÇÃO") + COUNTIFS(H39:H1988, A11 & CHAR(42), I39:I1988, "APROVADO")+ COUNTIFS(H39:H1988, A11 & CHAR(42), I39:I1988, "DIAGRAMADO") -> 10 | J11: =COUNTIFS(H39:H1985,A11 & "*", C39:C1985, "Cancelado") -> 1
A12: 957 | B12: UNIP MACAPA | C12: =COUNTIF(H40:H1965, A12 & "*") -> 64 | D12: =COUNTIFS(H:H, A12 & "*", I:I, "NAO ESTA NA PLANILHA") -> 30 | E12: =COUNTIFS(H:H, A12 & "*", C:C, "Entregue") -> 0 | F12: =COUNTIFS(H:H, A12 & "*", I:I,"IMPRESSÃO") -> 4 | G12: =COUNTIFS(H:H, A12 & "*", C:C, "Entregue") + COUNTIFS(H:H, A12 & "*", C:C, "No Estoque") + COUNTIFS(H:H, A12 & "*", I:I, "PRONTO") -> 3 | H12: =COUNTIFS(H40:H1965, A12 & "*", I40:I1965,"AGUARDANDO APROVAÇÃO") -> 6 | I12: =COUNTIFS(H40:H1989, A12 & CHAR(42), I40:I1989, "IMPRESSÃO") + COUNTIFS(H40:H1989, A12 & CHAR(42), I40:I1989, "AGUARDANDO APROVAÇÃO") + COUNTIFS(H40:H1989, A12 & CHAR(42), I40:I1989, "APROVADO")+ COUNTIFS(H40:H1989, A12 & CHAR(42), I40:I1989, "DIAGRAMADO") -> 13 | J12: =COUNTIFS(H40:H1986,A12 & "*", C40:C1986, "Cancelado") -> 6
A13: 961 | B13: UNIP PARAGOMINAS | C13: =COUNTIF(H41:H1966, A13 & "*") -> 8 | D13: =COUNTIFS(H:H, A13 & "*", I:I, "NAO ESTA NA PLANILHA") -> 4 | E13: =COUNTIFS(H:H, A13 & "*", C:C, "Entregue") -> 0 | F13: =COUNTIFS(H:H, A13 & "*", I:I,"IMPRESSÃO") -> 1 | G13: =COUNTIFS(H:H, A13 & "*", C:C, "Entregue") + COUNTIFS(H:H, A13 & "*", C:C, "No Estoque") + COUNTIFS(H:H, A13 & "*", I:I, "PRONTO") -> 0 | H13: =COUNTIFS(H41:H1966, A13 & "*", I41:I1966,"AGUARDANDO APROVAÇÃO") -> 2 | I13: =COUNTIFS(H41:H1990, A13 & CHAR(42), I41:I1990, "IMPRESSÃO") + COUNTIFS(H41:H1990, A13 & CHAR(42), I41:I1990, "AGUARDANDO APROVAÇÃO") + COUNTIFS(H41:H1990, A13 & CHAR(42), I41:I1990, "APROVADO")+ COUNTIFS(H41:H1990, A13 & CHAR(42), I41:I1990, "DIAGRAMADO") -> 3 | J13: =COUNTIFS(H41:H1987,A13 & "*", C41:C1987, "Cancelado") -> 0
A14: 971 | B14: UNAMA ALCINDO C | C14: =COUNTIF(H42:H1967, A14 & "*") -> 74 | D14: =COUNTIFS(H:H, A14 & "*", I:I, "NAO ESTA NA PLANILHA") -> 37 | E14: =COUNTIFS(H:H, A14 & "*", C:C, "Entregue") -> 9 | F14: =COUNTIFS(H:H, A14 & "*", I:I,"IMPRESSÃO") -> 2 | G14: =COUNTIFS(H:H, A14 & "*", C:C, "Entregue") + COUNTIFS(H:H, A14 & "*", C:C, "No Estoque") + COUNTIFS(H:H, A14 & "*", I:I, "PRONTO") -> 9 | H14: =COUNTIFS(H42:H1967, A14 & "*", I42:I1967,"AGUARDANDO APROVAÇÃO") -> 7 | I14: =COUNTIFS(H42:H1991, A14 & CHAR(42), I42:I1991, "IMPRESSÃO") + COUNTIFS(H42:H1991, A14 & CHAR(42), I42:I1991, "AGUARDANDO APROVAÇÃO") + COUNTIFS(H42:H1991, A14 & CHAR(42), I42:I1991, "APROVADO")+ COUNTIFS(H42:H1991, A14 & CHAR(42), I42:I1991, "DIAGRAMADO") -> 10 | J14: =COUNTIFS(H42:H1988,A14 & "*", C42:C1988, "Cancelado") -> 1
A15: 1103 | B15: UNIP CASTANHAL | C15: =COUNTIF(H43:H1968, A15 & "*") -> 32 | D15: =COUNTIFS(H:H, A15 & "*", I:I, "NAO ESTA NA PLANILHA") -> 18 | E15: =COUNTIFS(H:H, A15 & "*", C:C, "Entregue") -> 0 | F15: =COUNTIFS(H:H, A15 & "*", I:I,"IMPRESSÃO") -> 2 | G15: =COUNTIFS(H:H, A15 & "*", C:C, "Entregue") + COUNTIFS(H:H, A15 & "*", C:C, "No Estoque") + COUNTIFS(H:H, A15 & "*", I:I, "PRONTO") -> 0 | H15: =COUNTIFS(H43:H1968, A15 & "*", I43:I1968,"AGUARDANDO APROVAÇÃO") -> 0 | I15: =COUNTIFS(H43:H1992, A15 & CHAR(42), I43:I1992, "IMPRESSÃO") + COUNTIFS(H43:H1992, A15 & CHAR(42), I43:I1992, "AGUARDANDO APROVAÇÃO") + COUNTIFS(H43:H1992, A15 & CHAR(42), I43:I1992, "APROVADO")+ COUNTIFS(H43:H1992, A15 & CHAR(42), I43:I1992, "DIAGRAMADO") -> 2 | J15: =COUNTIFS(H43:H1989,A15 & "*", C43:C1989, "Cancelado") -> 6
A16: 1173 | B16: BOA VISTA | C16: =COUNTIF(H44:H1969, A16 & "*") -> 17 | D16: =COUNTIFS(H:H, A16 & "*", I:I, "NAO ESTA NA PLANILHA") -> 7 | E16: =COUNTIFS(H:H, A16 & "*", C:C, "Entregue") -> 0 | F16: =COUNTIFS(H:H, A16 & "*", I:I,"IMPRESSÃO") -> 2 | G16: =COUNTIFS(H:H, A16 & "*", C:C, "Entregue") + COUNTIFS(H:H, A16 & "*", C:C, "No Estoque") + COUNTIFS(H:H, A16 & "*", I:I, "PRONTO") -> 0 | H16: =COUNTIFS(H44:H1969, A16 & "*", I44:I1969,"AGUARDANDO APROVAÇÃO") -> 1 | I16: =COUNTIFS(H44:H1993, A16 & CHAR(42), I44:I1993, "IMPRESSÃO") + COUNTIFS(H44:H1993, A16 & CHAR(42), I44:I1993, "AGUARDANDO APROVAÇÃO") + COUNTIFS(H44:H1993, A16 & CHAR(42), I44:I1993, "APROVADO")+ COUNTIFS(H44:H1993, A16 & CHAR(42), I44:I1993, "DIAGRAMADO") -> 3 | J16: =COUNTIFS(H44:H1990,A16 & "*", C44:C1990, "Cancelado") -> 3
A17: 1177 | B17: SÃO LUIZ | C17: =COUNTIF(H45:H1970, A17 & "*") -> 13 | D17: =COUNTIFS(H:H, A17 & "*", I:I, "NAO ESTA NA PLANILHA") -> 5 | E17: =COUNTIFS(H:H, A17 & "*", C:C, "Entregue") -> 0 | F17: =COUNTIFS(H:H, A17 & "*", I:I,"IMPRESSÃO") -> 1 | G17: =COUNTIFS(H:H, A17 & "*", C:C, "Entregue") + COUNTIFS(H:H, A17 & "*", C:C, "No Estoque") + COUNTIFS(H:H, A17 & "*", I:I, "PRONTO") -> 0 | H17: =COUNTIFS(H45:H1970, A17 & "*", I45:I1970,"AGUARDANDO APROVAÇÃO") -> 4 | I17: =COUNTIFS(H45:H1994, A17 & CHAR(42), I45:I1994, "IMPRESSÃO") + COUNTIFS(H45:H1994, A17 & CHAR(42), I45:I1994, "AGUARDANDO APROVAÇÃO") + COUNTIFS(H45:H1994, A17 & CHAR(42), I45:I1994, "APROVADO")+ COUNTIFS(H45:H1994, A17 & CHAR(42), I45:I1994, "DIAGRAMADO") -> 5 | J17: =COUNTIFS(H45:H1991,A17 & "*", C45:C1991, "Cancelado") -> 1
A18: 1070 | B18: SMAC | C18: =COUNTIF(H46:H1971, A18 & "*") -> 10 | D18: =COUNTIFS(H:H, A18 & "*", I:I, "NAO ESTA NA PLANILHA") -> 6 | E18: =COUNTIFS(H:H, A18 & "*", C:C, "Entregue") -> 4 | F18: =COUNTIFS(H:H, A18 & "*", I:I,"IMPRESSÃO") -> 2 | G18: =COUNTIFS(H:H, A18 & "*", C:C, "Entregue") + COUNTIFS(H:H, A18 & "*", C:C, "No Estoque") + COUNTIFS(H:H, A18 & "*", I:I, "PRONTO") -> 4 | H18: =COUNTIFS(H46:H1971, A18 & "*", I46:I1971,"AGUARDANDO APROVAÇÃO") -> 0 | I18: =COUNTIFS(H46:H1995, A18 & CHAR(42), I46:I1995, "IMPRESSÃO") + COUNTIFS(H46:H1995, A18 & CHAR(42), I46:I1995, "AGUARDANDO APROVAÇÃO") + COUNTIFS(H46:H1995, A18 & CHAR(42), I46:I1995, "APROVADO")+ COUNTIFS(H46:H1995, A18 & CHAR(42), I46:I1995, "DIAGRAMADO") -> 2 | J18: =COUNTIFS(H46:H1992,A18 & "*", C46:C1992, "Cancelado") -> 0
A21: INDICADORES GERAIS
A22: Total de vendas | B22: =SUM(C4:C18) -> 662
A23: Total entregue | B23: =SUM(E4:E18) -> 23
A24: Total pendente de escolha | B24: =SUM(D4:D18) -> 278
A25: Total em IMPRESSAO | B25: =SUM(F4:F18) -> 35
A26: Total IMPRESSOS | B26: =SUM(G4:G18) -> 28
A27: Total EM APROVAÇAO | B27: =SUM(H4:H18) -> 63
A28: Total DIAGRAMADOS | B28: =SUM(I4:I18) -> 108
A29: TOTAL CANCELADOS | B29: =SUM(J4:J18) -> 19 | I29: {=IF(E29="", "", _xlfn.XLOOKUP(E29, 'GERAL ENVIOS'!C:C, 'GERAL ENVIOS'!K:K, "Não encontrado"))}
A31: CURSO | B31: ITEMS | C31: Status | D31: Cód. Cliente | E31: NOME | F31: E-mail | G31: Celular | H31: CONTRATO | I31: STATUS
B32: PACOTE BERLIM | C32: Enviado | D32: 89135 | E32: Andreia Da Silva Ferreira | F32: andreiaferreira66442@gmail.com | G32: (91) 981152574 | H32: 953 - UNIP BELÉM | I32: {=IF(E32="", "", _xlfn.XLOOKUP(E32, 'GERAL ENVIOS'!C:C, 'GERAL ENVIOS'!K:K,"NAO ESTA NA PLANILHA"))} -> NAO ESTA NA PLANILHA
B33: PACOTE MOSCOU | C33: Enviado | D33: 88679 | E33: Deolinda Dos Santos Borges | F33: deolinda.sborges@gmail.com | G33: (91) 980316385 | H33: 953 - UNIP BELÉM | I33: {=IF(E33="", "", _xlfn.XLOOKUP(E33, 'GERAL ENVIOS'!C:C, 'GERAL ENVIOS'!K:K,"NAO ESTA NA PLANILHA"))} -> NAO ESTA NA PLANILHA
B34: PACOTE BERLIM | C34: Enviado | D34: 88836 | E34: Deyse Thayane Bezerra Pontes | F34: pontesdeyse6@gmail.com | G34: (91) 991095971 | H34: 953 - UNIP BELÉM | I34: {=IF(E34="", "", _xlfn.XLOOKUP(E34, 'GERAL ENVIOS'!C:C, 'GERAL ENVIOS'!K:K,"NAO ESTA NA PLANILHA"))} -> NAO ESTA NA PLANILHA
B35: PACOTE BERLIM | C35: Enviado | D35: 88838 | E35: Donizete Henrique Bezerra Pontes | F35: donizetepontes2@gmail.com | G35: (91) 991933743 | H35: 953 - UNIP BELÉM | I35: {=IF(E35="", "", _xlfn.XLOOKUP(E35, 'GERAL ENVIOS'!C:C, 'GERAL ENVIOS'!K:K,"NAO ESTA NA PLANILHA"))} -> NAO ESTA NA PLANILHA
B36: PLANO DIAMOND BOOK | C36: Solicitado | D36: 75450 | E36: Eneida Viana Costa | F36: eneidavianaviana49@gmail.com | G36: (91) 98616-5775 | H36: 953 - UNIP BELÉM | I36: {=IF(E36="", "", _xlfn.XLOOKUP(E36, 'GERAL ENVIOS'!C:C, 'GERAL ENVIOS'!K:K,"NAO ESTA NA PLANILHA"))} -> NAO ESTA NA PLANILHA
B37: PACOTE MOSCOU | C37: Enviado | D37: 83848 | E37: Erivan Santana Brito | F37: erivanbrito24@gmail.com | G37: (91) 98015-8304 | H37: 953 - UNIP BELÉM | I37: {=IF(E37="", "", _xlfn.XLOOKUP(E37, 'GERAL ENVIOS'!C:C, 'GERAL ENVIOS'!K:K,"NAO ESTA NA PLANILHA"))} -> NAO ESTA NA PLANILHA
B38: PACOTE BERLIM | C38: Enviado | D38: 75856 | E38: Fabio De Castro Oliveira | F38: fabiodecastro406@gmail.com | G38: (91) 98525-5582 | H38: 953 - UNIP BELÉM | I38: {=IF(E38="", "", _xlfn.XLOOKUP(E38, 'GERAL ENVIOS'!C:C, 'GERAL ENVIOS'!K:K,"NAO ESTA NA PLANILHA"))} -> NAO ESTA NA PLANILHA
B39: PACOTE MOSCOU | C39: Enviado | D39: 88182 | E39: Fredson Luis Garcia Ribeiro | F39: fredsonnakata02@gmail.com | G39: (91) 984912140 | H39: 953 - UNIP BELÉM | I39: {=IF(E39="", "", _xlfn.XLOOKUP(E39, 'GERAL ENVIOS'!C:C, 'GERAL ENVIOS'!K:K,"NAO ESTA NA PLANILHA"))} -> NAO ESTA NA PLANILHA
B40: PACOTE MOSCOU | C40: Enviado | D40: 77934 | E40: Gabriela Lima Do Nascimento | F40: gabifitevolution@gmail.com | G40: (91) 980628643 | H40: 953 - UNIP BELÉM | I40: {=IF(E40="", "", _xlfn.XLOOKUP(E40, 'GERAL ENVIOS'!C:C, 'GERAL ENVIOS'!K:K,"NAO ESTA NA PLANILHA"))} -> NAO ESTA NA PLANILHA
B41: PACOTE BERLIM | C41: Enviado | D41: 88170 | E41: Jamilly Cristine Souza Silva | F41: jamillysouzasilva93@gmail.com | G41: (91) 985663920 | H41: 953 - UNIP BELÉM | I41: {=IF(E41="", "", _xlfn.XLOOKUP(E41, 'GERAL ENVIOS'!C:C, 'GERAL ENVIOS'!K:K,"NAO ESTA NA PLANILHA"))} -> NAO ESTA NA PLANILHA
B42: PACOTE MOSCOU | C42: Enviado | D42: 88620 | E42: Kamile Macedo Da Silva | F42: silvaakamile@gmail.com | G42: (91) 985845044 | H42: 953 - UNIP BELÉM | I42: {=IF(E42="", "", _xlfn.XLOOKUP(E42, 'GERAL ENVIOS'!C:C, 'GERAL ENVIOS'!K:K,"NAO ESTA NA PLANILHA"))} -> NAO ESTA NA PLANILHA
B43: PACOTE BERLIM | C43: Enviado | D43: 69817 | E43: Karolyne Pantoja Macedo | F43: karolynemacedo7@hotmail.com | G43: (91) 98457-1978 | H43: 953 - UNIP BELÉM | I43: {=IF(E43="", "", _xlfn.XLOOKUP(E43, 'GERAL ENVIOS'!C:C, 'GERAL ENVIOS'!K:K,"NAO ESTA NA PLANILHA"))} -> NAO ESTA NA PLANILHA
... B112: PACOTE MOSCOU | C112: Enviado | D112: 86794 | E112: Benedito Setuba Moura Junior | F112: 983372436j@gmail.com | G112: (91) 985164393 | H112: 1084 - UNAMA PS | I112: {=IF(E112="", "", _xlfn.XLOOKUP(E112, 'GERAL ENVIOS'!C:C, 'GERAL ENVIOS'!K:K,"NAO ESTA NA PLANILHA"))} -> NAO ESTA NA PLANILHA
...

Sheet LISTAGEM IMPRESSÃO
A1: FAMILY DAY
A2: FAMILY DAY
A3: 1º - Anna Carolina Monteiro Couto 20X20
A4: 1º - Arthur Henrique Carvalho Figueiredo 20x20
A5: 1º - Arthur Hiroshi Sousa Miyahara 20x20
A6: 1º - Arthur Pereira Guedes 20x20
A7: 1º - Brenda Kelly Auzier Marques 20x20
A8: 1º - Caetano Franca Kettle 20x20
A9: 1º - Camilly Vitoria Pereira Barbosa 30x20
A10: 1º - Diego Benjamin Souza Pires 20x20
A11: 1º - Emilly Vitória Assunção Nascimento 30x20
A12: 1º - Esmael da costa fontenele e Bianca 30x20
... A112: 4º - Ninna Maria Corrêa do Nascimento 30x20
A115: CONTROLE DE ENVIOS PARA A IMPRESSÃO | B115: LOTE 5
A116: FAMILY DAY | B116: QUITADO / PENDENTE
A117: 5º REMESSA (JOSELITO)
A118: Ana Clara Rodrigues Dias 30x20 | B118: QUITADA
A119: ANA JULIA TAVARES MARTINS 20x20 | B119: QUITADA
A120: Ana Lívia Santos de Alcantara 30X20 | B120: QUITADA
A121: ANA LUÍSA CUNHA DE ARAÚJO 20X20 | B121: QUITADA
A122: Ana Vitória Borges Kochhann 30x20 | B122: QUITADA
A123: ANDRÉ FELIPE MIRANDA DA SILVA 20X20 | B123: QUITADA
A124: Anna Luiza Machado da Silva 20X20 | B124: QUITADA
A125: Arcanjo Gabriel Ozorio Manacas 20X20 | B125: EM DIA
A126: Arthur Masao Watanabe Valente 30x20 | B126: QUITADA
A127: ARTUR FARIAS DE SOUZA 20X20 | B127: QUITADA
A128: Beatriz Shimada Gouvea Leão 20x20 | B128: QUITADA
A129: Benício Brasil Toso 30x20 | B129: QUITADA
... A153: Nicole Lima da Cunha 30x20 | B153: QUITADA
A154: Pedro Américo Ferreira Mazzinghy 30x20 | B154: QUITADA | D154: ok
A155: Pedro Davi Dos Santos Bentes 30X20 | B155: PENDENTE
A156: Rebeca dos anjos Cavalcante de Oliveira 20X20 | B156: QUITADA
A157: SARAH VITÓRIA SANTOS DA LUZ 30x20 | B157: QUITADA
A158: SOPHIA RODRIGUES DO VALE 20x20 | B158: QUITADA
A159: Uelber Rian Ferreira dos Anjos 30x20 | B159: QUITADA
A160: Victor Yuji Migiyama Vieira 30x20 | B160: QUITADA
A161: Yasmin Janaù Bastos da Silva 30x20 | B161: QUITADA
A162: Yuri Pereira de Farias 20x20 | B162: QUITADA
A164: COLAÇÃO JOSELITO | B164: LOTE 1
A165: Fernando Svein Silva Dos Santos 30x20 | B165: 971 | C165: ENTREGUE | D165: OK
...

Sheet IMPRESSÃO
A2: ÁLBUNS | M2: VALORES
A3: IMPRESSÃO - STATUS | B3: LOTE | C3: ESTOJOS 30X20 | D3: ESTOJOS 24X34 | E3: ALBUM 30X20 | F3: ALBUM 20X20 | G3: ALBUM 24X34 | H3: QUANTIDADE TOTAL | I3: GRÁFICA | J3: DATA DO PEDIDO | K3: PRAZO | L3: Coluna 1 | M3: EST 30X20 | N3: EST 24X34 | O3: VALOR 30X20 | P3: VALOR 20X20 | Q3: VALOR 24X34 | R3: VALOR TOTAL | S3: OBS | U3: JOSELITO
A4: PRONTO | B4: LOTE 1 A 4 - FAMILY | E4: 42 | F4: 68 | H4: =SUM(C4:G4) -> 110 | I4: JOSELITO | J4: 46174 | K4: 46236 | M4: =C4*37 -> 0 | N4: =D4*75 -> 0 | O4: =E4*141.35 -> 5936.7 | P4: =F4*59.4 -> 4039.2 | Q4: =G4*165 -> 0 | R4: =SUM(M4:Q4) -> 9975.9 | S4: PAGO | U4: 30x20 JOSELITO: R$ 190,00
A5: PRONTO | B5: LOTE 1 - COLAÇÃO | E5: 9 | F5: 2 | H5: =SUM(C5:G5) -> 11 | I5: JOSELITO | J5: 46175 | K5: 46237 | M5: =C5*37 -> 0 | N5: =D5*75 -> 0 | O5: =E5*141.35 -> 1272.15 | P5: =F5*59.4 -> 118.8 | Q5: =G5*165 -> 0 | R5: =SUM(M5:Q5) -> 1390.95 | S5: PAGO 01/06/2026 - COMPROVANTE WPP | U5: 20x20 JOSELITO: R$ 105,00
A6: PRONTO | B6: LOTE 2 - FAMILY E COLAÇÃO | E6: 29 | F6: 29 | H6: =SUM(C6:G6) -> 58 | I6: JOSELITO | J6: 46176 | K6: 46238 | M6: =C6*37 -> 0 | N6: =D6*75 -> 0 | O6: =E6*141.35 -> 4099.15 | P6: =F6*59.4 -> 1722.6 | Q6: =G6*165 -> 0 | R6: =SUM(M6:Q6) -> 5821.75 | S6: PG 3.000,00 08/06/26 - PG 3.000,00 15/06/26
A7: PRONTO | B7: AVULSO COLAÇÃO | D7: 6 | G7: 4 | H7: =SUM(C7:G7) -> 10 | I7: ZANGRAF | J7: 46177 | K7: 46239 | M7: =C7*37 -> 0 | N7: =D7*75 -> 450 | O7: =E7*141.35 -> 0 | P7: =F7*59.4 -> 0 | Q7: =G7*165 -> 660 | R7: =SUM(M7:Q7) -> 1110 | S7: OS 120517 / 120567 | U7: ZANGRAF
A8: PRONTO | B8: LOTE 1 - ESTOJO | C8: 39 | H8: =SUM(C8:G8) -> 39 | I8: GINEY | J8: 46178 | K8: 46240 | M8: =C8*37 -> 1443 | N8: =D8*75 -> 0 | O8: =E8*141.35 -> 0 | P8: =F8*59.4 -> 0 | Q8: =G8*165 -> 0 | R8: =SUM(M8:Q8) -> 1443 | U8: 30x20 estojo - 75,00 / 29,00 / 37,00
A9: PRONTO | B9: LOTE 3 - FAMILY E COLAÇÃO | E9: 45 | F9: 31 | H9: =SUM(C9:G9) -> 76 | I9: JOSELITO | J9: 46179 | K9: 46241 | M9: =C9*37 -> 0 | N9: =D9*75 -> 0 | O9: =E9*141.35 -> 6360.75 | P9: =F9*59.4 -> 1841.4 | Q9: =G9*165 -> 0 | R9: =SUM(M9:Q9) -> 8202.15 | S9: PG 3.000,00 / PG 2.000,00 / 5.960,00 / FALTA: 565,00 | U9: 24x34 estojo - 75,00
A10: PRONTO | B10: LOTE 4 - COLAÇÃO | E10: 11 | F10: 13 | G10: 12 | H10: =SUM(C10:G10) -> 36 | I10: ZANGRAF | J10: 46180 | K10: 46242 | M10: =C10*37 -> 0 | N10: =D10*75 -> 0 | O10: =E10*141.35 -> 1554.85 | P10: =F10*59.4 -> 772.2 | Q10: =G10*165 -> 1980 | R10: =SUM(M10:Q10) -> 4307.05 | U10: Álbum 30x20 - 141,35
A11: PRONTO | B11: LOTE 5 - COLAÇÃO | E11: 23 | H11: =SUM(C11:G11) -> 23 | I11: ZANGRAF | J11: 46210 | K11: 46240 | M11: =C11*37 -> 0 | N11: =D11*75 -> 0 | O11: =E11*141.35 -> 3251.05 | P11: =F11*59.4 -> 0 | Q11: =G11*165 -> 0 | R11: =SUM(M11:Q11) -> 3251.05 | U11: Álbum 34x24 - 165,00
A12: PRONTO | B12: LOTE 6 - COLAÇÃO | C12: 23 | H12: =SUM(C12:G12) -> 23 | I12: ZANGRAF | J12: 46211 | K12: 46241 | M12: =C12*37 -> 851 | N12: =D12*75 -> 0 | O12: =E12*141.35 -> 0 | P12: =F12*59.4 -> 0 | Q12: =G12*165 -> 0 | R12: =SUM(M12:Q12) -> 851 | U12: Álbum 20x20 - 59,40
A13: PRONTO | B13: LOTE 7 - COLAÇÃO | C13: 17 | D13: 14 | E13: 17 | F13: 15 | G13: 14 | H13: =SUM(C13:G13) -> 77 | I13: ZANGRAF | J13: 46212 | K13: =J13+45 -> 46257 | M13: =C13*37 -> 629 | N13: =D13*75 -> 1050 | O13: =E13*141.35 -> 2402.95 | P13: =F13*59.4 -> 891 | Q13: =G13*165 -> 2310 | R13: =SUM(M13:Q13) -> 7282.95
A14: PRONTO | B14: LOTE 8 - COLAÇÃO | C14: 9 | D14: 3 | E14: 9 | F14: 4 | G14: 3 | H14: =SUM(C14:G14) -> 28 | I14: ZANGRAF | J14: 46212 | K14: =J14+45 -> 46257 | M14: =C14*37 -> 333 | N14: =D14*75 -> 225 | O14: =E14*141.35 -> 1272.15 | P14: =F14*59.4 -> 237.6 | Q14: =G14*165 -> 495 | R14: =SUM(M14:Q14) -> 2562.75
A15: PRONTO | B15: LOTE 9 - COLAÇÃO | C15: 15 | D15: 8 | E15: 15 | F15: 9 | G15: 8 | H15: =SUM(C15:G15) -> 55 | I15: ZANGRAF | J15: 46224 | K15: =J15+45 -> 46269 | M15: =C15*37 -> 555 | N15: =D15*75 -> 600 | O15: =E15*141.35 -> 2120.25 | P15: =F15*59.4 -> 534.6 | Q15: =G15*165 -> 1320 | R15: =SUM(M15:Q15) -> 5129.85
A16: EM PRODUÇÃO | B16: LOTE 7 - FAMILY | C16: 8 | E16: 8 | F16: 7 | H16: =SUM(C16:G16) -> 23 | I16: JOSELITO | J16: 46225 | K16: 46243 | M16: =C16*37 -> 296 | N16: =D16*75 -> 0 | O16: =E16*141.35 -> 1130.8 | P16: =F16*59.4 -> 415.8 | Q16: =G16*165 -> 0 | R16: =SUM(M16:Q16) -> 1842.6
A17: EM PRODUÇÃO | B17: LOTE 8 - FAMILY | E17: 8 | F17: 18 | H17: =SUM(C17:G17) -> 26 | I17: JOSELITO | J17: 46241 | K17: 46256 | M17: =C17*37 -> 0 | N17: =D17*75 -> 0 | O17: =E17*141.35 -> 1130.8 | P17: =F17*59.4 -> 1069.2 | Q17: =G17*165 -> 0 | R17: =SUM(M17:Q17) -> 2200 | S17: adicionar no valor total + 190 de um 30x20 por fora
A18: PRONTO | B18: LOTE 10 - COLAÇÃO | C18: 9 | D18: 10 | E18: 9 | F18: 13 | G18: 10 | H18: =SUM(C18:G18) -> 42 | I18: ZANGRAF | J18: 46235 | K18: =J18+45 -> 46280 | M18: =C18*37 -> 333 | N18: =D18*75 -> 750 | O18: =E18*141.35 -> 1272.15 | P18: =F18*59.4 -> 772.2 | Q18: =G18*165 -> 1650 | R18: =SUM(M18:Q18) -> 4777.35
A19: PRONTO | B19: LOTE 11 - COLAÇÃO | C19: 15 | D19: 9 | E19: 15 | F19: 10 | G19: 9 | H19: =SUM(C19:G19) -> 58 | I19: ZANGRAF | J19: 46253 | K19: =J19+45 -> 46298 | M19: =C19*37 -> 555 | N19: =D19*75 -> 675 | O19: =E19*141.35 -> 2120.25 | P19: =F19*59.4 -> 594 | Q19: =G19*165 -> 1485 | R19: =SUM(M19:Q19) -> 5429.25
A20: EM PRODUÇÃO | B20: LOTE 12 - COLAÇÃO | C20: 19 | D20: 12 | E20: 19 | F20: 16 | G20: 12 | H20: =SUM(C20:G20) -> 78 | I20: ZANGRAF | J20: 46272 | K20: =J20+45 -> 46317 | M20: =C20*37 -> 703 | N20: =D20*75 -> 900 | O20: =E20*141.35 -> 2685.65 | P20: =F20*59.4 -> 950.4 | Q20: =G20*165 -> 1980 | R20: =SUM(M20:Q20) -> 7219.05
A21: EM PRODUÇÃO | B21: LOTE 13 - COLAÇÃO | C21: 15 | D21: 5 | E21: 15 | F21: 11 | G21: 5 | H21: =SUM(C21:G21) -> 51 | I21: ZANGRAF | J21: 46274 | K21: =J21+45 -> 46319 | M21: =C21*37 -> 555 | N21: =D21*75 -> 375 | O21: =E21*141.35 -> 2120.25 | P21: =F21*59.4 -> 653.4 | Q21: =G21*165 -> 825 | R21: =SUM(M21:Q21) -> 4528.65
A22: EM PRODUÇÃO | B22: LOTE 14 - COLAÇÃO | H22: =SUM(C22:G22) -> 0 | I22: ZANGRAF | J22: 46275 | K22: =J22+45 -> 46320 | M22: =C22*37 -> 0 | N22: =D22*75 -> 0 | O22: =E22*141.35 -> 0 | P22: =F22*59.4 -> 0 | Q22: =G22*165 -> 0 | R22: =SUM(M22:Q22) -> 0
A23: EM PRODUÇÃO | B23: LOTE 15 - COLAÇÃO | H23: =SUM(C23:G23) -> 0 | I23: ZANGRAF | J23: 46276 | K23: =J23+45 -> 46321 | M23: =C23*37 -> 0 | N23: =D23*75 -> 0 | O23: =E23*141.35 -> 0 | P23: =F23*59.4 -> 0 | Q23: =G23*165 -> 0 | R23: =SUM(M23:Q23) -> 0
A24: EM PRODUÇÃO | B24: LOTE 16 - COLAÇÃO | H24: =SUM(C24:G24) -> 0 | I24: ZANGRAF | J24: 46277 | K24: =J24+45 -> 46322 | M24: =C24*37 -> 0 | N24: =D24*75 -> 0 | O24: =E24*141.35 -> 0 | P24: =F24*59.4 -> 0 | Q24: =G24*165 -> 0 | R24: =SUM(M24:Q24) -> 0
A25: EM PRODUÇÃO | B25: LOTE 17 | H25: =SUM(C25:G25) -> 0 | I25: ZANGRAF | J25: 46278 | K25: =J25+45 -> 46323 | M25: =C25*37 -> 0 | N25: =D25*75 -> 0 | O25: =E25*141.35 -> 0 | P25: =F25*59.4 -> 0 | Q25: =G25*165 -> 0 | R25: =SUM(M25:Q25) -> 0
A32: DIAGRAMAÇÃO COLAÇÃO | B32: LOTE | C32: 20x20 | D32: 24X34 | E32: 30x20 | F32: PREÇO | G32: HELLEN | H32: VALOR REF | J32: SACOLAS DE VELUDO | K32: M | L32: G | M32: DATA DO PEDIDO | N32: TOTAL
A33: PRONTO | B33: LOTE 1 | C33: 5 | D33: 5 | E33: 11 | F33: R$ 570,00 | G33: PAGO | H33: 20X20 | I33: 15 | J33: AGUARDANDO PAGAMENTO INICIAL | K33: 100 | L33: 40 | M33: 46178 | N33: R$ 2.940,00
A34: PRONTO | B34: LOTE 2 | C34: 0 | D34: 1 | E34: 29 | F34: R$ 530,00 | G34: PAGO | H34: 24X34 | I34: 20
A35: PRONTO | B35: LOTE 3 | C35: 5 | D35: 11 | E35: 6 | F35: R$ 415,00 | G35: PAGO - 09/06 | H35: 30X20 | I35: 20
A36: PRONTO | B36: LOTE 4 | C36: 16 | D36: 17 | E36: 17 | F36: R$ 760,00
A37: PRONTO | B37: LOTE 5 | C37: 8 | D37: 11 | E37: 5 | F37: =C37*I33+D37*I34+E37*I35 -> 440
A38: PRONTO | B38: LOTE 6 | C38: 10 | D38: 10 | E38: 10 | F38: =C38*15+D38*20+E38*20 -> 550
A39: PRONTO | B39: LOTE 7 | C39: 7 | D39: 9 | E39: 4 | F39: =C39*15+D39*20+E39*20 -> 365
A40: PRONTO | B40: LOTE 08/09 | C40: 16 | D40: 12 | E40: 7 | F40: =C40*15+D40*20+E40*20 -> 620
A41: PRONTO | B41: LOTE 02/10 | C41: 4 | D41: 13 | E41: 4 | F41: =C41*15+D41*20+E41*20 -> 400
A42: PRONTO | B42: 46304 | C42: 0 | D42: 0 | E42: 7 | F42: =C42*15+D42*20+E42*20 -> 140
A43: EM PRODUÇAO | B43: 46311 | C43: 1 | D43: 1 | E43: 3 | F43: =C43*15+D43*20+E43*20 -> 95
A44: EM PRODUÇAO | F44: =C44*15+D44*20+E44*20 -> 0
A45: EM PRODUÇAO | F45: =C45*15+D45*20+E45*20 -> 0
A46: EM PRODUÇAO | F46: =C46*15+D46*20+E46*20 -> 0
A47: EM PRODUÇAO | F47: =C47*15+D47*20+E47*20 -> 0
...
